[2022-08-09 16:28:55,583] [views.py:43] [views:get_set] [ERROR]- OperationalError('no such column: account.account_status')
[2022-08-09 16:43:55,093] [views.py:94] [views:delete_account] [ERROR]- FieldError("Cannot resolve keyword 'account_id' into field. Choices are: robot_account_id, robot_create_time, robot_currency_type, robot_id, robot_policy_id, robot_policy_type, robot_status, robot_summary_id")
[2022-08-09 16:46:49,364] [log.py:228] [log:log_response] [ERROR]- Internal Server Error: /api/get_set
Traceback (most recent call last):
  File "C:\Users\wispytrace\anaconda3\envs\bituniverse\lib\site-packages\django\core\handlers\exception.py", line 34, in inner
    response = get_response(request)
  File "C:\Users\wispytrace\anaconda3\envs\bituniverse\lib\site-packages\django\core\handlers\base.py", line 115, in _get_response
    response = self.process_exception_by_middleware(e, request)
  File "C:\Users\wispytrace\anaconda3\envs\bituniverse\lib\site-packages\django\core\handlers\base.py", line 113, in _get_response
    response = wrapped_callback(request, *callback_args, **callback_kwargs)
  File "H:\code\bituniverse\django\bitApp\views.py", line 44, in get_set
    return JsonResponse(ret)
  File "C:\Users\wispytrace\anaconda3\envs\bituniverse\lib\site-packages\django\http\response.py", line 558, in __init__
    data = json.dumps(data, cls=encoder, **json_dumps_params)
  File "C:\Users\wispytrace\anaconda3\envs\bituniverse\lib\json\__init__.py", line 238, in dumps
    **kw).encode(obj)
  File "C:\Users\wispytrace\anaconda3\envs\bituniverse\lib\json\encoder.py", line 199, in encode
    chunks = self.iterencode(o, _one_shot=True)
  File "C:\Users\wispytrace\anaconda3\envs\bituniverse\lib\json\encoder.py", line 257, in iterencode
    return _iterencode(o, 0)
  File "C:\Users\wispytrace\anaconda3\envs\bituniverse\lib\site-packages\django\core\serializers\json.py", line 104, in default
    return super().default(o)
  File "C:\Users\wispytrace\anaconda3\envs\bituniverse\lib\json\encoder.py", line 179, in default
    raise TypeError(f'Object of type {o.__class__.__name__} '
TypeError: Object of type set is not JSON serializable
[2022-08-09 16:46:49,366] [basehttp.py:154] [basehttp:log_message] [ERROR]- "POST /api/get_set HTTP/1.1" 500 96105
[2022-08-09 16:46:51,099] [log.py:228] [log:log_response] [ERROR]- Internal Server Error: /api/get_set
Traceback (most recent call last):
  File "C:\Users\wispytrace\anaconda3\envs\bituniverse\lib\site-packages\django\core\handlers\exception.py", line 34, in inner
    response = get_response(request)
  File "C:\Users\wispytrace\anaconda3\envs\bituniverse\lib\site-packages\django\core\handlers\base.py", line 115, in _get_response
    response = self.process_exception_by_middleware(e, request)
  File "C:\Users\wispytrace\anaconda3\envs\bituniverse\lib\site-packages\django\core\handlers\base.py", line 113, in _get_response
    response = wrapped_callback(request, *callback_args, **callback_kwargs)
  File "H:\code\bituniverse\django\bitApp\views.py", line 44, in get_set
    return JsonResponse(ret)
  File "C:\Users\wispytrace\anaconda3\envs\bituniverse\lib\site-packages\django\http\response.py", line 558, in __init__
    data = json.dumps(data, cls=encoder, **json_dumps_params)
  File "C:\Users\wispytrace\anaconda3\envs\bituniverse\lib\json\__init__.py", line 238, in dumps
    **kw).encode(obj)
  File "C:\Users\wispytrace\anaconda3\envs\bituniverse\lib\json\encoder.py", line 199, in encode
    chunks = self.iterencode(o, _one_shot=True)
  File "C:\Users\wispytrace\anaconda3\envs\bituniverse\lib\json\encoder.py", line 257, in iterencode
    return _iterencode(o, 0)
  File "C:\Users\wispytrace\anaconda3\envs\bituniverse\lib\site-packages\django\core\serializers\json.py", line 104, in default
    return super().default(o)
  File "C:\Users\wispytrace\anaconda3\envs\bituniverse\lib\json\encoder.py", line 179, in default
    raise TypeError(f'Object of type {o.__class__.__name__} '
TypeError: Object of type set is not JSON serializable
[2022-08-09 16:46:51,099] [basehttp.py:154] [basehttp:log_message] [ERROR]- "POST /api/get_set HTTP/1.1" 500 96105
[2022-08-09 16:46:52,413] [log.py:228] [log:log_response] [ERROR]- Internal Server Error: /api/get_set
Traceback (most recent call last):
  File "C:\Users\wispytrace\anaconda3\envs\bituniverse\lib\site-packages\django\core\handlers\exception.py", line 34, in inner
    response = get_response(request)
  File "C:\Users\wispytrace\anaconda3\envs\bituniverse\lib\site-packages\django\core\handlers\base.py", line 115, in _get_response
    response = self.process_exception_by_middleware(e, request)
  File "C:\Users\wispytrace\anaconda3\envs\bituniverse\lib\site-packages\django\core\handlers\base.py", line 113, in _get_response
    response = wrapped_callback(request, *callback_args, **callback_kwargs)
  File "H:\code\bituniverse\django\bitApp\views.py", line 44, in get_set
    return JsonResponse(ret)
  File "C:\Users\wispytrace\anaconda3\envs\bituniverse\lib\site-packages\django\http\response.py", line 558, in __init__
    data = json.dumps(data, cls=encoder, **json_dumps_params)
  File "C:\Users\wispytrace\anaconda3\envs\bituniverse\lib\json\__init__.py", line 238, in dumps
    **kw).encode(obj)
  File "C:\Users\wispytrace\anaconda3\envs\bituniverse\lib\json\encoder.py", line 199, in encode
    chunks = self.iterencode(o, _one_shot=True)
  File "C:\Users\wispytrace\anaconda3\envs\bituniverse\lib\json\encoder.py", line 257, in iterencode
    return _iterencode(o, 0)
  File "C:\Users\wispytrace\anaconda3\envs\bituniverse\lib\site-packages\django\core\serializers\json.py", line 104, in default
    return super().default(o)
  File "C:\Users\wispytrace\anaconda3\envs\bituniverse\lib\json\encoder.py", line 179, in default
    raise TypeError(f'Object of type {o.__class__.__name__} '
TypeError: Object of type set is not JSON serializable
[2022-08-09 16:46:52,413] [basehttp.py:154] [basehttp:log_message] [ERROR]- "POST /api/get_set HTTP/1.1" 500 96105
[2022-08-09 16:46:57,853] [log.py:228] [log:log_response] [ERROR]- Internal Server Error: /api/get_set
Traceback (most recent call last):
  File "C:\Users\wispytrace\anaconda3\envs\bituniverse\lib\site-packages\django\core\handlers\exception.py", line 34, in inner
    response = get_response(request)
  File "C:\Users\wispytrace\anaconda3\envs\bituniverse\lib\site-packages\django\core\handlers\base.py", line 115, in _get_response
    response = self.process_exception_by_middleware(e, request)
  File "C:\Users\wispytrace\anaconda3\envs\bituniverse\lib\site-packages\django\core\handlers\base.py", line 113, in _get_response
    response = wrapped_callback(request, *callback_args, **callback_kwargs)
  File "H:\code\bituniverse\django\bitApp\views.py", line 44, in get_set
    return JsonResponse(ret)
  File "C:\Users\wispytrace\anaconda3\envs\bituniverse\lib\site-packages\django\http\response.py", line 558, in __init__
    data = json.dumps(data, cls=encoder, **json_dumps_params)
  File "C:\Users\wispytrace\anaconda3\envs\bituniverse\lib\json\__init__.py", line 238, in dumps
    **kw).encode(obj)
  File "C:\Users\wispytrace\anaconda3\envs\bituniverse\lib\json\encoder.py", line 199, in encode
    chunks = self.iterencode(o, _one_shot=True)
  File "C:\Users\wispytrace\anaconda3\envs\bituniverse\lib\json\encoder.py", line 257, in iterencode
    return _iterencode(o, 0)
  File "C:\Users\wispytrace\anaconda3\envs\bituniverse\lib\site-packages\django\core\serializers\json.py", line 104, in default
    return super().default(o)
  File "C:\Users\wispytrace\anaconda3\envs\bituniverse\lib\json\encoder.py", line 179, in default
    raise TypeError(f'Object of type {o.__class__.__name__} '
TypeError: Object of type set is not JSON serializable
[2022-08-09 16:46:57,854] [basehttp.py:154] [basehttp:log_message] [ERROR]- "POST /api/get_set HTTP/1.1" 500 96105
[2022-08-09 16:57:36,938] [views.py:162] [views:get_robot_info] [ERROR]- ProxyError(MaxRetryError("HTTPSConnectionPool(host='api.huobi.pro', port=443): Max retries exceeded with url: /v1/account/accounts/33269501/balance?account-id=33269501&AccessKeyId=5cd285c0-bewr5drtmh-a21ed20a-46286&SignatureVersion=2&SignatureMethod=HmacSHA256&Timestamp=2022-08-09T08%3A57%3A17&Signature=2fd07v0ijX8V1wFTsf0ev7w2DiYzB0mUWoyzhcoIlBE%3D (Caused by ProxyError('Cannot connect to proxy.', RemoteDisconnected('Remote end closed connection without response')))"))
[2022-08-09 17:21:11,434] [views.py:162] [views:get_robot_info] [ERROR]- ProxyError(MaxRetryError("HTTPSConnectionPool(host='api.huobi.pro', port=443): Max retries exceeded with url: /v1/account/accounts/33269501/balance?account-id=33269501&AccessKeyId=5cd285c0-bewr5drtmh-a21ed20a-46286&SignatureVersion=2&SignatureMethod=HmacSHA256&Timestamp=2022-08-09T09%3A20%3A52&Signature=usPcs1t%2FBD22TXtRxebvEjXQDno5WMyhYHJZmW2094A%3D (Caused by ProxyError('Cannot connect to proxy.', RemoteDisconnected('Remote end closed connection without response')))"))
[2022-08-09 17:25:49,804] [robot.py:180] [robot:cancel_order] [ERROR]- HuobiApiException('ExecuteError', '[Executing] order-orderstate-error: Incorrect order state')
[2022-08-09 17:25:49,964] [robot.py:180] [robot:cancel_order] [ERROR]- HuobiApiException('ExecuteError', '[Executing] order-orderstate-error: Incorrect order state')
[2022-08-09 17:25:50,128] [robot.py:180] [robot:cancel_order] [ERROR]- HuobiApiException('ExecuteError', '[Executing] order-orderstate-error: Incorrect order state')
[2022-08-09 17:25:50,299] [robot.py:180] [robot:cancel_order] [ERROR]- HuobiApiException('ExecuteError', '[Executing] order-orderstate-error: Incorrect order state')
[2022-08-09 17:25:50,484] [robot.py:180] [robot:cancel_order] [ERROR]- HuobiApiException('ExecuteError', '[Executing] order-orderstate-error: Incorrect order state')
[2022-08-09 17:25:50,487] [robot.py:190] [robot:cancel_orders] [ERROR]- Exception('撤销订单失败')
[2022-08-09 17:25:50,648] [robot.py:180] [robot:cancel_order] [ERROR]- HuobiApiException('ExecuteError', '[Executing] order-orderstate-error: Incorrect order state')
[2022-08-09 17:25:50,806] [robot.py:180] [robot:cancel_order] [ERROR]- HuobiApiException('ExecuteError', '[Executing] order-orderstate-error: Incorrect order state')
[2022-08-09 17:25:50,972] [robot.py:180] [robot:cancel_order] [ERROR]- HuobiApiException('ExecuteError', '[Executing] order-orderstate-error: Incorrect order state')
[2022-08-09 17:25:51,131] [robot.py:180] [robot:cancel_order] [ERROR]- HuobiApiException('ExecuteError', '[Executing] order-orderstate-error: Incorrect order state')
[2022-08-09 17:25:51,293] [robot.py:180] [robot:cancel_order] [ERROR]- HuobiApiException('ExecuteError', '[Executing] order-orderstate-error: Incorrect order state')
[2022-08-09 17:25:51,294] [robot.py:190] [robot:cancel_orders] [ERROR]- Exception('撤销订单失败')
[2022-08-09 17:25:51,457] [robot.py:180] [robot:cancel_order] [ERROR]- HuobiApiException('ExecuteError', '[Executing] order-orderstate-error: Incorrect order state')
[2022-08-09 17:25:51,623] [robot.py:180] [robot:cancel_order] [ERROR]- HuobiApiException('ExecuteError', '[Executing] order-orderstate-error: Incorrect order state')
[2022-08-09 17:25:51,782] [robot.py:180] [robot:cancel_order] [ERROR]- HuobiApiException('ExecuteError', '[Executing] order-orderstate-error: Incorrect order state')
[2022-08-09 17:25:51,943] [robot.py:180] [robot:cancel_order] [ERROR]- HuobiApiException('ExecuteError', '[Executing] order-orderstate-error: Incorrect order state')
[2022-08-09 17:25:52,113] [robot.py:180] [robot:cancel_order] [ERROR]- HuobiApiException('ExecuteError', '[Executing] order-orderstate-error: Incorrect order state')
[2022-08-09 17:25:52,113] [robot.py:190] [robot:cancel_orders] [ERROR]- Exception('撤销订单失败')
